<?xml version="1.0" encoding="utf-8"?>
<!-- This URDF was automatically created by SolidWorks to URDF Exporter! Originally created by Stephen Brawner (brawner@gmail.com) 
     Commit Version: 1.6.0-1-g15f4949  Build Version: 1.6.7594.29634
     For more information, please see http://wiki.ros.org/sw_urdf_exporter -->
<robot
  name="ee_tip">
  <link
    name="base_link">
    <inertial>
      <origin
        xyz="2.82378534434436E-18 -0.0227581511174895 3.82068943351184E-18"
        rpy="0 0 0" />
      <mass
        value="0.0814159265358979" />
      <inertia
        ixx="0.000121913816960056"
        ixy="-4.329016012952E-20"
        ixz="2.01977829715946E-20"
        iyy="8.49041296601283E-05"
        iyz="6.9098351648537E-21"
        izz="0.000121913816960056" />
    </inertial>
    <visual>
      <origin
        xyz="0 0 0"
        rpy="0 0 0" />
      <geometry>
        <mesh
          filename="package://ee_tip/meshes/base_link.STL" />
      </geometry>
      <material
        name="">
        <color
          rgba="0.792156862745098 0.819607843137255 0.933333333333333 1" />
      </material>
    </visual>
    <collision>
      <origin
        xyz="0 0 0"
        rpy="0 0 0" />
      <geometry>
        <mesh
          filename="package://ee_tip/meshes/base_link.STL" />
      </geometry>
    </collision>
  </link>
  <link
    name="link1">
    <inertial>
      <origin
        xyz="-5.45993780887765E-17 -2.57729904459674E-18 -0.0822418488825105"
        rpy="0 0 0" />
      <mass
        value="0.081415926535898" />
      <inertia
        ixx="0.000121913816960056"
        ixy="2.75285707857648E-21"
        ixz="3.4663661937145E-20"
        iyy="0.000121913816960056"
        iyz="2.50902565773603E-21"
        izz="8.49041296601284E-05" />
    </inertial>
    <visual>
      <origin
        xyz="0 0 0"
        rpy="0 0 0" />
      <geometry>
        <mesh
          filename="package://ee_tip/meshes/link1.STL" />
      </geometry>
      <material
        name="">
        <color
          rgba="0.792156862745098 0.819607843137255 0.933333333333333 1" />
      </material>
    </visual>
    <collision>
      <origin
        xyz="0 0 0"
        rpy="0 0 0" />
      <geometry>
        <mesh
          filename="package://ee_tip/meshes/link1.STL" />
      </geometry>
    </collision>
  </link>
  <joint
    name="joint1"
    type="continuous">
    <origin
      xyz="0 -0.105 0"
      rpy="-1.5707963267949 -0.0161784886231073 0" />
    <parent
      link="base_link" />
    <child
      link="link1" />
    <axis
      xyz="0 0 1" />
  </joint>
</robot>