<?xml version="1.0" encoding="utf-8"?>
<!-- This URDF was automatically created by SolidWorks to URDF Exporter! Originally created by Stephen Brawner (brawner@gmail.com) 
     Commit Version: 1.6.0-1-g15f4949  Build Version: 1.6.7594.29634
     For more information, please see http://wiki.ros.org/sw_urdf_exporter -->
     
     
<robot name="mcl_3dof">
 <link name="world">
  </link>
  <joint name="world_joint" type="fixed">
    <origin rpy="-1.57079632679 0 0" xyz="0 0 0"/>
    <parent link="world"/>
    <child link="base_link"/>
  </joint>


  <link
    name="base_link">
    <inertial>
      <origin
        xyz="0.00335973734681663 -0.0146414571501169 -0.187115131343177"
        rpy="0 0 0" />
      <mass
        value="0.575312098629904" />
      <inertia
        ixx="0.000976860907479915"
        ixy="5.6935351186025E-06"
        ixz="3.68004375471235E-07"
        iyy="0.00106899249682209"
        iyz="3.2744266391575E-08"
        izz="0.00146540545473797" />
    </inertial>
    <visual>
      <origin
        xyz="0 0 0"
        rpy="0 0 0" />
      <geometry>
        <mesh
          filename="package://mcl_3dof/meshes/base_link.STL" />
      </geometry>
      <material
        name="">
        <color
          rgba="0.345098039215686 0.733333333333333 0.52156862745098 1" />
      </material>
    </visual>
  </link>
  
  <link
    name="link1">
    <inertial>
      <origin
        xyz="-0.000292428726635939 3.80854294984856E-05 0.164883706799653"
        rpy="0 0 0" />
      <mass
        value="0.631863379368706" />
      <inertia
        ixx="0.00349564569100285"
        ixy="-2.23656255099292E-07"
        ixz="8.58361961733456E-06"
        iyy="0.00361188454025062"
        iyz="-1.97332266315382E-06"
        izz="0.000713794955779595" />
    </inertial>
    <visual>
      <origin
        xyz="0 0 0"
        rpy="0 0 0" />
      <geometry>
        <mesh
          filename="package://mcl_3dof/meshes/link1.STL" />
      </geometry>
      <material
        name="">
        <color
          rgba="0.345098039215686 0.733333333333333 0.52156862745098 1" />
      </material>
    </visual>
  </link>
  <joint
    name="joint1"
    type="continuous">
    <origin
      xyz="0.00410079032708863 -0.0632593003752511 -0.187116007773175"
      rpy="1.5707963267949 0 0" />
    <parent
      link="base_link" />
    <child
      link="link1" />
    <axis
      xyz="0 0 1" />
  </joint>
  <link
    name="link2">
    <inertial>
      <origin
        xyz="-0.000453971112807189 -3.29159131652323E-05 0.164992703924591"
        rpy="0 0 0" />
      <mass
        value="0.578111145755757" />
      <inertia
        ixx="0.00289421111034152"
        ixy="-1.39763578175677E-07"
        ixz="9.26902120781876E-05"
        iyy="0.00327308044990143"
        iyz="1.13669211701003E-06"
        izz="0.000999124926649504" />
    </inertial>
    <visual>
      <origin
        xyz="0 0 0"
        rpy="0 0 0" />
      <geometry>
        <mesh
          filename="package://mcl_3dof/meshes/link2.STL" />
      </geometry>
      <material
        name="">
        <color
          rgba="0.345098039215686 0.733333333333333 0.52156862745098 1" />
      </material>
    </visual>
  </link>
  <joint
    name="joint2"
    type="continuous">
    <origin
      xyz="0 0 0.206"
      rpy="0 0 0" />
    <parent
      link="link1" />
    <child
      link="link2" />
    <axis
      xyz="1 0 0" />
  </joint>
  <link
    name="link3">
    <inertial>
      <origin
        xyz="-0.00239101178166537 2.48815534832636E-05 0.110327577602884"
        rpy="0 0 0" />
      <mass
        value="0.238635029623959" />
      <inertia
        ixx="0.00139480285143715"
        ixy="-2.19044444827235E-07"
        ixz="3.24497158896E-05"
        iyy="0.0017611599255438"
        iyz="-5.9590342130969E-08"
        izz="0.000600330561767098" />
    </inertial>
    <visual>
      <origin
        xyz="0 0 0"
        rpy="0 0 0" />
      <geometry>
        <mesh
          filename="package://mcl_3dof/meshes/link3.STL" />
      </geometry>
      <material
        name="">
        <color
          rgba="0.898039215686275 0.917647058823529 0.929411764705882 1" />
      </material>
    </visual>
  </link>
  <joint
    name="joint3"
    type="continuous">
    <origin
      xyz="0 0 0.203"
      rpy="0 0 0" />
    <parent
      link="link2" />
    <child
      link="link3" />
    <axis
      xyz="1 0 0" />
  </joint>
</robot>
