<?xml version="1.0" encoding="utf-8"?>
<!-- This URDF was automatically created by SolidWorks to URDF Exporter! Originally created by Stephen Brawner (brawner@gmail.com) 
     Commit Version: 1.6.0-1-g15f4949  Build Version: 1.6.7594.29634
     For more information, please see http://wiki.ros.org/sw_urdf_exporter -->

<robot  name="mcl_3dof">
  <link name="world">
  </link>
  
  <joint name="world_joint" type="fixed">
    <origin rpy="0 0 0" xyz="0 0 0"/>
    <parent link="world"/>
    <child link="base_link"/>
  </joint>

  <link
    name="base_link">
    <inertial>
      <origin
        xyz="-3.20239446884824E-05 0.00032179014494665 0.0780255416330852"
        rpy="0 0 0" />
      <mass
        value="2.97210866060567" />
      <inertia
        ixx="0.014807736439744"
        ixy="-8.69247379621563E-06"
        ixz="2.89184892240664E-06"
        iyy="0.00849183892118372"
        iyz="5.25177651071248E-05"
        izz="0.0112118233526831" />
    </inertial>
    <visual>
      <origin
        xyz="0 0 0"
        rpy="0 0 0" />
      <geometry>
        <mesh filename="../meshes/base_link.STL" />
      </geometry>
      <material
        name="">
        <color
          rgba="0.898039215686275 0.917647058823529 0.929411764705882 1" />
      </material>
    </visual>
    <collision>
      <origin
        xyz="0 0 0"
        rpy="0 0 0" />
      <geometry>
        <mesh filename="../meshes/base_link.obj"/>
      </geometry>
    </collision>
  </link>
  <link
    name="link1">
    <inertial>
      <origin
        xyz="1.86833906878572E-05 1.45068360348307E-05 0.212803532023699"
        rpy="0 0 0" />
      <mass
        value="3.28985374204315" />
      <inertia
        ixx="0.0151239724035253"
        ixy="1.02356042177397E-06"
        ixz="1.03115381341261E-05"
        iyy="0.0138456038375166"
        iyz="9.37533006050866E-05"
        izz="0.00881894422233837" />
    </inertial>
    <visual>
      <origin
        xyz="0 0 0"
        rpy="0 0 0" />
      <geometry>
        <mesh filename="../meshes/link1.STL" />
      </geometry>
      <material
        name="">
        <color
          rgba="0.898039215686275 0.917647058823529 0.929411764705882 1" />
      </material>
    </visual>
    <collision>
      <origin
        xyz="0 0 0"
        rpy="0 0 0" />
      <geometry>
        <mesh filename="../meshes/link1.obj" />
      </geometry>
    </collision>
  </link>
  <joint
    name="joint1"
    type="continuous">
    <origin
      xyz="0 0 0.0569507847000184"
      rpy="0 0 0.00120056804630435" />
    <parent
      link="base_link" />
    <child
      link="link1" />
    <axis
      xyz="0 0 1" />
  </joint>
  <link
    name="link2">
    <inertial>
      <origin
        xyz="0.274430322773381 -0.0204550458921208 0.0116404391422537"
        rpy="0 0 0" />
      <mass
        value="3.93881568442974" />
      <inertia
        ixx="0.0128883627908592"
        ixy="-0.0078049528947116"
        ixz="0.000402684704067785"
        iyy="0.141176626946427"
        iyz="-6.43548505834082E-05"
        izz="0.139610408794833" />
    </inertial>
    <visual>
      <origin
        xyz="0 0 0"
        rpy="0 0 0" />
      <geometry>
        <mesh filename="../meshes/link2.STL" />
      </geometry>
      <material
        name="">
        <color
          rgba="0.898039215686275 0.917647058823529 0.929411764705882 1" />
      </material>
    </visual>
    <collision>
      <origin
        xyz="0 0 0"
        rpy="0 0 0" />
      <geometry>
        <mesh filename="../meshes/link2.obj" />
      </geometry>
    </collision>
  </link>
  <joint
    name="joint2"
    type="continuous">
    <origin
      xyz="0 0 0.228049215299977"
      rpy="1.57079632679392 -1.56463020306352 -3.14159265358881" />
    <parent
      link="link1" />
    <child
      link="link2" />
    <axis
      xyz="4.75788938438077E-05 -0.00771607786742558 -0.999970229496155" />
  </joint>
  <link
    name="link3">
    <inertial>
      <origin
        xyz="0.166452398578567 -0.0254845690494124 0.0112186426280152"
        rpy="0 0 0" />
      <mass
        value="1.59657531450204" />
      <inertia
        ixx="0.00510958910338134"
        ixy="-0.00166532924683158"
        ixz="0.00112209993348911"
        iyy="0.0393229089455213"
        iyz="-5.2549110378132E-05"
        izz="0.0380493609237414" />
    </inertial>
    <visual>
      <origin
        xyz="0 0 0"
        rpy="0 0 0" />
      <geometry>
        <mesh filename="../meshes/link3.STL" />
      </geometry>
      <material
        name="">
        <color
          rgba="0.898039215686275 0.917647058823529 0.929411764705882 1" />
      </material>
    </visual>
    <collision>
      <origin
        xyz="0 0 0"
        rpy="0 0 0" />
      <geometry>
        <mesh filename="../meshes/link3.obj" />
      </geometry>
    </collision>
  </link>
  <joint
    name="joint3"
    type="continuous">
    <origin
      xyz="0.449877646861617 0.0104928216795562 -5.95605214722162E-05"
      rpy="0 0 0.0429632498504854" />
    <parent
      link="link2" />
    <child
      link="link3" />
    <axis
      xyz="-0.000283870816533773 -0.00771100115204504 -0.999970229496155" />
  </joint>
  <link
    name="link_ee">
    <inertial>
      <origin
        xyz="0.22422 -4.7578E-06 -1.6916E-05"
        rpy="0 0 0" />
      <mass
        value="0.12473" />
      <inertia
        ixx="6.785E-05"
        ixy="5.3487E-12"
        ixz="-1.9213E-09"
        iyy="6.4014E-05"
        iyz="1.0158E-08"
        izz="6.2949E-05" />
    </inertial>
    <visual>
      <origin
        xyz="0 0 0"
        rpy="0 0 0" />
      <geometry>
        <mesh
          filename="../meshes/link_ee.STL" />
      </geometry>
      <material
        name="">
          <contact name="ice"/>
        <color
          rgba="0.20392 0.20392 0.20392 1" />
      </material>
    </visual>
    <collision>
      <origin
        xyz="0 0 0"
        rpy="0 0 0" />
      <geometry>
        <mesh
          filename="../meshes/link_ee.obj" />
      </geometry>
    </collision>
  </link>
  <joint
    name="joint_ee"
    type="fixed">
    <origin
      xyz="0.44867 -0.010488 0.0075596"
      rpy="0 0 1.5707" />
    <parent
      link="link3" />
    <child
      link="link_ee" />
    <axis
      xyz="0 0 0" />
  </joint>

  <joint name="joint_ee_tip" type="fixed">
    <parent link="link_ee"/>
    <child link="ee_tip"/>
    <origin rpy="0 0 0" xyz="0 -0.075 0.0"/>      
    <axis xyz="0 0 1"/>
  </joint>  
       
  <link name="ee_tip">
      <inertial>
      <origin rpy="0 0 0" xyz="0 0 0"/>
      <mass value="0"/>
      <inertia ixx="0.0" ixy="0.0" ixz="0.0" iyy="0.0" iyz="0.0" izz="0.0"/>
    </inertial>  
  </link>
  
</robot>
